Workbook

Sheet 4-Synthése Questions   
A1: Dans cette section nous allons essayer d'identifier les freins d'accès aux marchés qui vous intéressent. On rappelle que des freins sont des obstacles vous empêchant d'envisager d'entrer dans ces marchés, ce ne sont pas des simples difficultés surmontables facilement. il ne faudra pas donc répondre oui à toutes les questions
B2: VGT | C2: Marché | E2: Veille sur les marchés | G2: Equipements | J2: Logistique manquante ou inefficace | L2: Frein lié aux formations | P2: Frein lié à l' accès au financement
D3: Est intéressé (Oui/Non) | E3: Accès limité sur les opportunités du marché | F3: Accès limité au fonctionnement du marché | G3: Stockage | H3: Conditionnement | I3: Conservation | J3: Moyen de transport – FREIN (version détaillée comme tu veux) | K3: Coût du transport – FREIN (version détaillée comme tu veux) | L3: Formation normes & qualité – FREIN | M3: Formation administrative – FREIN | N3: Formation numérique – FREIN | O3: Formation marketing / négociations – FREIN | P3: Financement équipement – FREIN | Q3: Financement formation normes/qualité – FREIN | R3: Financement formation marketing / négociations– FREIN | S3: Financement formation numérique – FREIN | T3: Financement formation administrative – FREIN | U3: Financement développement global – FREIN | V3: Préfinancement commandes – FREIN
B4: 1 | C4: Vente à domicile ou auprès d’amis | E4: Considérez-vous que le manque d’information sur les opportunités locales (besoin des voisins, lieux où trouver des clients potentiels, petits points de rencontre) constitue un frein pour augmenter vos ventes ? | F4: Considérez-vous que le manque d’informations sur la manière d’organiser la vente à domicile (prix adaptés, modalités de livraison locale, règles informelles du quartier) constitue un frein à vos ventes ?
B5: 2 | C5: Marché local (village / petite ville) | D5: Souhaitez-vous accéder à ce type de marché ? | E5: =+'Veille sur le marché'!$B$4 -> 5 | F5: =+'Veille sur le marché'!$B$5 -> 5 | G5: =+'Frein au marché '!B4 -> 11 | H5: =+'Frein au marché '!C4 -> 8 | I5: =+'Frein au marché '!D4 -> 9 | J5: =+'Frein au marché '!E4 -> 9 | K5: =+'Frein au marché '!F4 -> 9 | L5: =+'Frein au marché '!G4 -> 10 | M5: =+'Frein au marché '!H4 -> 11 | N5: =+'Frein au marché '!I4 -> 9 | ... V5: =+'Frein au marché '!Q4 -> 14 | W5: =SUM(E5:V5) -> 188
B6: 3 | C6: Marché Grossistes / Semi-grossistes, Grandes surfaces / Supermarchés, hôtels | D6: Souhaitez-vous accéder à ce type de marché ? | E6: =+'Veille sur le marché'!$C$4 -> 21 | F6: =+'Veille sur le marché'!$C$5 -> 20 | G6: =+'Frein au marché '!B5 -> 18 | H6: =+'Frein au marché '!C5 -> 16 | I6: =+'Frein au marché '!D5 -> 15 | J6: =+'Frein au marché '!E5 -> 22 | K6: =+'Frein au marché '!F5 -> 20 | L6: =+'Frein au marché '!G5 -> 15 | M6: =+'Frein au marché '!H5 -> 14 | N6: =+'Frein au marché '!I5 -> 13 | ... V6: =+'Frein au marché '!Q5 -> 20 | W6: =SUM(E6:V6) -> 317
B7: 4 | C7: Marché de l’Etat : cantines, hôpitaux, écoles, ministères (commandes publiques) | D7: Souhaitez-vous accéder à ce type de marché ? | E7: =+'Veille sur le marché'!$D$4 -> 10 | F7: =+'Veille sur le marché'!$D$5 -> 10 | G7: =+'Frein au marché '!B6 -> 9 | H7: =+'Frein au marché '!C6 -> 9 | I7: =+'Frein au marché '!D6 -> 8 | J7: =+'Frein au marché '!E6 -> 6 | K7: =+'Frein au marché '!F6 -> 6 | L7: =+'Frein au marché '!G6 -> 6 | M7: =+'Frein au marché '!H6 -> 6 | N7: =+'Frein au marché '!I6 -> 6 | ... V7: =+'Frein au marché '!Q6 -> 10 | W7: =SUM(E7:V7) -> 148
B8: 5 | C8: Marché numérique (Facebook, Tiktok, Whatsapp, etc.) | D8: Souhaitez-vous accéder à ce type de marché ? | E8: =+'Veille sur le marché'!$E$4 -> 8 | F8: =+'Veille sur le marché'!$E$5 -> 5 | G8: =+'Frein au marché '!B7 -> 8 | H8: =+'Frein au marché '!C7 -> 5 | I8: =+'Frein au marché '!D7 -> 9 | J8: =+'Frein au marché '!E7 -> 10 | K8: =+'Frein au marché '!F7 -> 10 | L8: =+'Frein au marché '!G7 -> 10 | M8: =+'Frein au marché '!H7 -> 8 | N8: =+'Frein au marché '!I7 -> 7 | ... V8: =+'Frein au marché '!Q7 -> 11 | W8: =SUM(E8:V8) -> 165
B9: 6 | C9: Marché de la sous region | D9: Souhaitez-vous accéder à ce type de marché ? | E9: =+'Veille sur le marché'!$F$4 -> 23 | F9: =+'Veille sur le marché'!$F$5 -> 23 | G9: =+'Frein au marché '!B8 -> 20 | H9: =+'Frein au marché '!C8 -> 18 | I9: =+'Frein au marché '!D8 -> 20 | J9: =+'Frein au marché '!E8 -> 21 | K9: =+'Frein au marché '!F8 -> 25 | L9: =+'Frein au marché '!G8 -> 24 | M9: =+'Frein au marché '!H8 -> 20 | N9: =+'Frein au marché '!I8 -> 19 | ... V9: =+'Frein au marché '!Q8 -> 24 | W9: =SUM(E9:V9) -> 401
B10: 7 | C10: Marché export (à l’étranger) | D10: Souhaitez-vous accéder à ce type de marché ? | E10: =+'Veille sur le marché'!$G$4 -> 21 | F10: =+'Veille sur le marché'!$G$5 -> 21 | G10: =+'Frein au marché '!B9 -> 19 | H10: =+'Frein au marché '!C9 -> 17 | I10: =+'Frein au marché '!D9 -> 21 | J10: =+'Frein au marché '!E9 -> 21 | K10: =+'Frein au marché '!F9 -> 22 | L10: =+'Frein au marché '!G9 -> 20 | M10: =+'Frein au marché '!H9 -> 18 | N10: =+'Frein au marché '!I9 -> 17 | ... V10: =+'Frein au marché '!Q9 -> 22 | W10: =SUM(E10:V10) -> 363

Sheet Analyse resultats
T1: Niveau 1 (Marché Local) | AL1: Niveau 2 (Marché des grossistes) | BD1: Niveau 3 (Marché de l'Etat) | BV1: Niveau 4 (Marché numérique) | CN1: Niveau 5 (Marché de la sous region) | CQ1: Niveau 5 (Marché de la sous region) | DF1: Niveau 6 (Marché internationnal )
T2: Veille sur les marchés | V2: Equipements | Y2: Logistique manquante ou inefficace | AA2: Frein lié aux formations | AE2: Frein lié à l' accès au financement | AL2: Veille sur les marchés | AN2: Equipements | AQ2: Logistique manquante ou inefficace | AS2: Frein lié aux formations | AW2: Frein lié à l' accès au financement | BD2: Veille sur les marchés | BF2: Equipements | BI2: Logistique manquante ou inefficace | BK2: Frein lié aux formations | BO2: Frein lié à l' accès au financement | BV2: Veille sur les marchés | BX2: Equipements | CA2: Logistique manquante ou inefficace | CC2: Frein lié aux formations | CG2: Frein lié à l' accès au financement | CN2: Veille sur les marchés | CP2: Equipements | CS2: Logistique manquante ou inefficace | CU2: Frein lié aux formations | CY2: Frein lié à l' accès au financement | DF2: Veille sur les marchés | DH2: Equipements | DK2: Logistique manquante ou inefficace | DM2: Frein lié aux formations | DQ2: Frein lié à l' accès au financement
A3: # | B3: Nom de l'entreprise | C3: Tel | D3: Ville | E3: longitude | F3: latittude | G3: Effectif | H3: Volume de production mensuel | I3: Structure d'accompagnement | J3: CA FCFA | K3: Filières | L3: Produits | M3: Ancienneté | N3: Marché local (du village / petite ville) | O3: Marché Grossistes / Semi-grossistes, Grandes surfaces / supermarchés, hotels, | P3: Marché de l’Etat (commandes publiques cantine , école, ) | Q3: Marché numérique (vente en ligne, facebook, tiktok….whatsapp.. ;etc) | R3: Marché sous régional (Gabon , nigeri….....) | S3: Marché export (à l’étranger) | T3: Accès limité sur les opportunités du marché | U3: Accès limité au fonctionnement du marché | V3: Stockage | W3: Conditionnement | X3: Conservation | Y3: Moyen de transport – FREIN (version détaillée comme tu veux) | Z3: Coût du transport – FREIN (version détaillée comme tu veux) | AA3: Formation normes & qualité – FREIN | AB3: Formation administrative – FREIN | AC3: Formation numérique – FREIN | AD3: Formation marketing / négociations – FREIN | AE3: Financement équipement – FREIN | AF3: Financement formation normes/qualité – FREIN | AG3: Financement formation marketing / négociations– FREIN | AH3: Financement formation numérique – FREIN | AI3: Financement formation administrative – FREIN | AJ3: Financement développement global – FREIN | AK3: Préfinancement commandes – FREIN | AL3: Accès limité sur les opportunités du marché | AM3: Accès limité au fonctionnement du marché | AN3: Stockage | AO3: Conditionnement | AP3: Conservation | AQ3: Moyen de transport – FREIN (version détaillée comme tu veux) | AR3: Coût du transport – FREIN (version détaillée comme tu veux) | AS3: Formation normes & qualité – FREIN | AT3: Formation administrative – FREIN | AU3: Formation numérique – FREIN | AV3: Formation marketing / négociations – FREIN | AW3: Financement équipement – FREIN | AX3: Financement formation normes/qualité – FREIN | AY3: Financement formation marketing / négociations– FREIN | AZ3: Financement formation numérique – FREIN | BA3: Financement formation administrative – FREIN | BB3: Financement développement global – FREIN | BC3: Préfinancement commandes – FREIN | BD3: Accès limité sur les opportunités du marché | BE3: Accès limité au fonctionnement du marché | BF3: Stockage | BG3: Conditionnement | BH3: Conservation | BI3: Moyen de transport – FREIN (version détaillée comme tu veux) | BJ3: Coût du transport – FREIN (version détaillée comme tu veux) | BK3: Formation normes & qualité – FREIN | BL3: Formation administrative – FREIN | BM3: Formation numérique – FREIN | BN3: Formation marketing / négociations – FREIN | BO3: Financement équipement – FREIN | BP3: Financement formation normes/qualité – FREIN | BQ3: Financement formation marketing / négociations– FREIN | BR3: Financement formation numérique – FREIN | BS3: Financement formation administrative – FREIN | BT3: Financement développement global – FREIN | BU3: Préfinancement commandes – FREIN | BV3: Accès limité sur les opportunités du marché | BW3: Accès limité au fonctionnement du marché | BX3: Stockage | BY3: Conditionnement | BZ3: Conservation | CA3: Moyen de transport – FREIN (version détaillée comme tu veux) | CB3: Coût du transport – FREIN (version détaillée comme tu veux) | CC3: Formation normes & qualité – FREIN | CD3: Formation administrative – FREIN | CE3: Formation numérique – FREIN | CF3: Formation marketing / négociations – FREIN | CG3: Financement équipement – FREIN | CH3: Financement formation normes/qualité – FREIN | CI3: Financement formation marketing / négociations– FREIN | CJ3: Financement formation numérique – FREIN | CK3: Financement formation administrative – FREIN | CL3: Financement développement global – FREIN | CM3: Préfinancement commandes – FREIN | CN3: Accès limité sur les opportunités du marché | CO3: Accès limité au fonctionnement du marché | CP3: Stockage | CQ3: Conditionnement | CR3: Conservation | CS3: Moyen de transport – FREIN (version détaillée comme tu veux) | CT3: Coût du transport – FREIN (version détaillée comme tu veux) | CU3: Formation normes & qualité – FREIN | CV3: Formation administrative – FREIN | CW3: Formation numérique – FREIN | CX3: Formation marketing / négociations – FREIN | CY3: Financement équipement – FREIN | CZ3: Financement formation normes/qualité – FREIN | DA3: Financement formation marketing / négociations– FREIN | DB3: Financement formation numérique – FREIN | DC3: Financement formation administrative – FREIN | DD3: Financement développement global – FREIN | DE3: Préfinancement commandes – FREIN | DF3: Accès limité sur les opportunités du marché | DG3: Accès limité au fonctionnement du marché | DH3: Stockage | DI3: Conditionnement | DJ3: Conservation | DK3: Moyen de transport – FREIN (version détaillée comme tu veux) | DL3: Coût du transport – FREIN (version détaillée comme tu veux) | DM3: Formation normes & qualité – FREIN | DN3: Formation administrative – FREIN | DO3: Formation numérique – FREIN | DP3: Formation marketing / négociations – FREIN | DQ3: Financement équipement – FREIN | DR3: Financement formation normes/qualité – FREIN | DS3: Financement formation marketing / négociations– FREIN | DT3: Financement formation numérique – FREIN | DU3: Financement formation administrative – FREIN | DV3: Financement développement global – FREIN | DW3: Préfinancement commandes – FREIN | DX3: n
A4: 1 | B4: GIC DJOUMA | D4: Bamguel, Maroua | E4: 14° 03′ Est | F4: 10° 48′ Nord | G4: 20 | H4: 50 sacs par saison | I4: NON | J4: 15000000 | K4: Fruits et légumes | L4: Oignons | M4: 10 | N4: OUI | O4: NON | P4: NON | Q4: NON | R4: NON | S4: NON | T4: NON | U4: NON | V4: OUI | W4: OUI | X4: OUI | Y4: OUI | Z4: OUI | AA4: OUI | AB4: OUI | AC4: OUI | AD4: OUI | AE4: OUI | AF4: OUI | AG4: OUI | AH4: OUI | AI4: OUI | AJ4: OUI | AK4: OUI | AL4: OUI | AM4: OUI | AN4: OUI | AO4: NON | AP4: NON | AQ4: OUI | AR4: OUI | AS4: - | AT4: - | AU4: - | AV4: - | AW4: OUI | AY4: OUI | AZ4: OUI | BA4: OUI | BB4: OUI | BC4: OUI
A5: 2 | B5: NDOUMESSI | D5: Kribi, Centre | E5: 9,9167° E | F5: 2,9250° N | G5: 1 | H5: 500 poules - 6 mois | I5: NON | J5: 1200000 | K5: Volaile de chair | L5: Volaile de chair | M5: 2 | N5: OUI | O5: NON | P5: NON | Q5: NON | R5: NON | S5: NON | T5: NON | U5: NON | V5: NON | W5: NON | X5: NON | Y5: NON | Z5: NON | AA5: NON | AB5: NON | AC5: NON | AD5: NON | AE5: NON | AF5: NON | AG5: NON | AH5: NON | AI5: NON | AJ5: NON | AK5: NON | AL5: OUI | AM5: OUI | AN5: NON | AO5: OUI | AP5: NON | AQ5: OUI | AR5: OUI | AS5: NON | AT5: NON | AU5: NON | AV5: NON | AW5: NON | AX5: NON | AY5: NON | AZ5: NON | BA5: NON | BB5: OUI | BC5: NON | BD5: NON | BE5: NON | BF5: NON | BG5: NON | BH5: NON | BI5: NON | BJ5: NON | BK5: NON | BL5: NON | BM5: NON | BN5: NON | BO5: NON | BP5: NON | BQ5: NON | BR5: NON | BS5: NON | BT5: NON | BU5: NON | BV5: NON | BW5: NON | BX5: NON | BY5: NON | BZ5: NON | CA5: NON | CB5: NON | CC5: NON | CD5: NON | CE5: NON | CF5: NON | CG5: NON | CH5: NON | CI5: NON | CJ5: NON | CK5: NON | CL5: NON | CM5: NON | CN5: NON | CO5: NON | CP5: NON | CQ5: NON | CR5: NON | CS5: NON | CT5: NON | CU5: NON | CV5: NON | CW5: NON | CX5: NON | CY5: NON | CZ5: NON | DA5: NON | DB5: NON | DC5: NON | DD5: NON | DE5: NON | DF5: NON | DG5: NON | DH5: NON | DI5: NON | DJ5: NON | DK5: NON | DL5: NON | DM5: NON | DN5: NON | DO5: NON | DP5: NON | DQ5: NON | DR5: NON | DS5: NON | DT5: NON | DU5: NON | DV5: NON | DW5: NON
A6: 3 | B6: GIC PRODUCTEURS DES OIGNONS | C6: 675020727 | D6: Nord | E6: 13.393389 | F6: 9.3226016 | G6: 7 | H6: 37 fois 4 par saison | I6: NON | J6: 3700000 | K6: Fruits et légumes | L6: Oignons | M6: 2 | N6: OUI | O6: NON | P6: NON | Q6: NON | R6: NON | S6: NON | T6: NON | U6: NON | V6: NON | W6: NON | X6: NON | Y6: NON | Z6: NON | AA6: NON | AB6: NON | AC6: NON | AD6: NON | AE6: NON | AF6: NON | AG6: NON | AH6: NON | AI6: NON | AJ6: NON | AK6: NON | AL6: OUI | AM6: OUI | AN6: NON | AO6: NON | AP6: NON | AQ6: OUI | AR6: OUI | AS6: OUI | AT6: OUI | AU6: OUI | AV6: OUI | AW6: OUI | AX6: OUI | AY6: OUI | AZ6: OUI | BA6: OUI | BB6: OUI | BC6: OUI | BD6: NON | BE6: NON | BF6: NON | BG6: NON | BH6: NON | BI6: NON | BJ6: NON | BK6: NON | BL6: NON | BM6: NON | BN6: NON | BO6: NON | BP6: NON | BQ6: NON | BR6: NON | BS6: NON | BT6: NON | BU6: NON | BV6: OUI | BW6: OUI | BX6: OUI | BY6: OUI | BZ6: NON | CA6: OUI | CB6: OUI | CC6: OUI | CD6: OUI | CE6: OUI | CF6: OUI | CG6: OUI | CH6: OUI | CI6: OUI | CJ6: OUI | CK6: OUI | CL6: OUI | CM6: OUI | CN6: NON | CO6: NON | CP6: NON | CQ6: NON | CR6: NON | CS6: NON | CT6: NON | CU6: NON | CV6: NON | CW6: NON | CX6: NON | CY6: NON | CZ6: NON | DA6: NON | DB6: NON | DC6: NON | DD6: NON | DE6: NON | DF6: NON | DG6: NON | DH6: NON | DI6: NON | DJ6: NON | DK6: NON | DL6: NON | DM6: NON | DN6: NON | DO6: NON | DP6: NON | DQ6: NON | DR6: NON | DS6: NON | DT6: NON | DU6: NON | DV6: NON | DW6: NON
A7: 4 | B7: GIC PRODUCTEURS DES PEPINIERES DE MAYO-LOUE | C7: 699701299 | D7: Nord | E7: 13,2174246° E | F7: 8,2410564° N | G7: 16 | H7: 32 sacs | I7: NON | J7: 1500000 | K7: Fruits et légumes | L7: Piment | M7: 10 | N7: OUI | O7: OUI | P7: NON | Q7: NON | R7: NON | S7: NON | T7: NON | U7: NON | V7: NON | W7: NON | X7: NON | Y7: NON | Z7: NON | AA7: NON | AB7: NON | AC7: NON | AD7: NON | AE7: NON | AF7: NON | AG7: NON | AH7: NON | AI7: NON | AJ7: NON | AK7: NON | AL7: NON | AM7: NON | AN7: NON | AO7: NON | AP7: NON | AQ7: NON | AR7: NON | AS7: NON | AT7: NON | AU7: NON | AV7: NON | AW7: NON | AX7: NON | AY7: NON | AZ7: NON | BA7: NON | BB7: NON | BC7: NON | BD7: NON | BE7: NON | BF7: NON | BG7: NON | BH7: NON | BI7: NON | BJ7: NON | BK7: NON | BL7: NON | BM7: NON | BN7: NON | BO7: NON | BP7: NON | BQ7: NON | BR7: NON | BS7: NON | BT7: NON | BU7: NON | BV7: NON | BW7: NON | BX7: NON | BY7: NON | BZ7: NON | CA7: NON | CB7: NON | CC7: NON | CD7: NON | CE7: NON | CF7: NON | CG7: NON | CH7: NON | CI7: NON | CJ7: NON | CK7: NON | CL7: NON | CM7: NON | CN7: OUI | CO7: OUI | CP7: OUI | CQ7: OUI | CR7: NON | CS7: OUI | CT7: OUI | CU7: OUI | CV7: OUI | CW7: OUI | CX7: OUI | CY7: OUI | CZ7: OUI | DA7: OUI | DB7: OUI | DC7: OUI | DD7: OUI | DE7: OUI | DF7: NON | DG7: NON | DH7: NON | DI7: NON | DJ7: NON | DK7: NON | DL7: NON | DM7: NON | DN7: NON | DO7: NON | DP7: NON | DQ7: NON | DR7: NON | DS7: NON | DT7: NON | DU7: NON | DV7: NON | DW7: NON
A8: 5 | B8: GIC MADINA DES PRODUCTEURS DES CULTURES MARAICHERES DE BARGARAM | C8: 652591465 | D8: Ilarifa, Extreme nord | E8: 14° 57' 00" Est | F8: 12° 26' 24" Nord | G8: 13 | H8: 50 Sacs de par an | I8: NON | J8: 2500000 | K8: Fruits et légumes | L8: Piment | M8: 10 | N8: OUI | O8: NON | P8: NON | Q8: NON | R8: NON | S8: NON | T8: NON | U8: NON | V8: NON | W8: NON | X8: NON | Y8: NON | Z8: NON | AA8: NON | AB8: NON | AC8: NON | AD8: NON | AE8: NON | AF8: NON | AG8: NON | AH8: NON | AI8: NON | AJ8: NON | AK8: NON | AL8: NON | AM8: NON | AN8: NON | AO8: NON | AP8: NON | AQ8: NON | AR8: NON | AS8: NON | AT8: NON | AU8: NON | AV8: NON | AW8: NON | AX8: NON | AY8: NON | AZ8: NON | BA8: NON | BB8: NON | BC8: NON | BD8: NON | BE8: NON | BF8: NON | BG8: NON | BH8: NON | BI8: NON | BJ8: NON | BK8: NON | BL8: NON | BM8: NON | BN8: NON | BO8: NON | BP8: NON | BQ8: NON | BR8: NON | BS8: NON | BT8: NON | BU8: NON | BV8: OUI | BW8: OUI | BX8: NON | BY8: NON | BZ8: NON | CA8: OUI | CB8: OUI | CC8: NON | CD8: OUI | CE8: OUI | CF8: OUI | CG8: OUI | CH8: OUI | CI8: OUI | CJ8: OUI | CK8: OUI | CL8: OUI | CM8: NON | CN8: NON | CO8: NON | CP8: NON | CQ8: NON | CR8: NON | CS8: NON | CT8: NON | CU8: NON | CV8: NON | CW8: NON | CX8: NON | CY8: NON | CZ8: NON | DA8: NON | DB8: NON | DC8: NON | DD8: NON | DE8: NON | DF8: NON | DG8: NON | DH8: NON | DI8: NON | DJ8: NON | DK8: NON | DL8: NON | DM8: NON | DN8: NON | DO8: NON | DP8: NON | DQ8: NON | DR8: NON | DS8: NON | DT8: NON | DU8: NON | DV8: NON | DW8: NON
A9: 6 | B9: groupe des élèves de Volaille de Rouge | C9: 676502725 | D9: Donry-BENOUE | E9: 13.393389 | F9: 9.3226016 | G9: 11 | H9: voliume par saison : 2024(14 tonnes) et 2025(10 tonnes) | I9: NON | J9: 2000000 | K9: Volaile de chair | L9: Volaile et production de mais | M9: 14 | N9: OUI | O9: NON | P9: NON | Q9: NON | R9: NON | S9: NON | T9: OUI | U9: OUI | V9: OUI | W9: OUI | X9: OUI | Y9: OUI | Z9: OUI | AA9: OUI | AB9: OUI | AC9: OUI | AD9: OUI | AE9: OUI | AF9: OUI | AG9: OUI | AH9: OUI | AI9: OUI | AJ9: OUI | AK9: OUI | AL9: NON | AM9: NON | AN9: NON | AO9: NON | AP9: NON | AQ9: NON | AR9: NON | AS9: NON | AT9: NON | AU9: NON | AV9: NON | AW9: NON | AX9: NON | AY9: NON | AZ9: NON | BA9: NON | BB9: NON | BC9: NON | BD9: NON | BE9: NON | BF9: NON | BG9: NON | BH9: NON | BI9: NON | BJ9: NON | BK9: NON | BL9: NON | BM9: NON | BN9: NON | BO9: NON | BP9: NON | BQ9: NON | BR9: NON | BS9: NON | BT9: NON | BU9: NON | BV9: NON | BW9: NON | BX9: NON | BY9: NON | BZ9: NON | CA9: NON | CB9: NON | CC9: NON | CD9: NON | CE9: NON | CF9: NON | CG9: NON | CH9: NON | CI9: NON | CJ9: NON | CK9: NON | CL9: NON | CM9: NON | CN9: NON | CO9: NON | CP9: NON | CQ9: NON | CR9: NON | CS9: NON | CT9: NON | CU9: NON | CV9: NON | CW9: NON | CX9: NON | CY9: NON | CZ9: NON | DA9: NON | DB9: NON | DC9: NON | DD9: NON | DE9: NON | DF9: NON | DG9: NON | DH9: NON | DI9: NON | DJ9: NON | DK9: NON | DL9: NON | DM9: NON | DN9: NON | DO9: NON | DP9: NON | DQ9: NON | DR9: NON | DS9: NON | DT9: NON | DU9: NON | DV9: NON | DW9: NON
A10: 7 | B10: Société coopérative simplifiée des éleveurs de poulet, de chair | C10: 691772660 | D10: NASSARAO-GAROUA | E10: 13,59838° | F10: 9,91167° | G10: 40 | H10: environ 600 alvéoles d'oeufs par jour | I10: NON | J10: 1200000 | K10: Volaile de chair | L10: poulet pondeuse et maîs | M10: 5 | N10: OUI | O10: OUI | P10: NON | Q10: NON | R10: NON | S10: NON | V10: OUI | W10: OUI | X10: OUI | Y10: NON | Z10: NON | AA10: NON | AB10: NON | AC10: NON | AD10: NON | AE10: NON | AF10: NON | AG10: NON | AH10: NON | AI10: NON | AJ10: NON | AK10: NON | AN10: NON | AQ10: NON | AR10: NON | AS10: NON | AT10: NON | AU10: NON | AV10: NON | AW10: NON | AX10: NON | AY10: NON | AZ10: NON | BA10: NON | BB10: NON | BC10: NON | BD10: NON | BE10: NON | BF10: NON | BG10: NON | BH10: NON | BI10: NON | BJ10: NON | BK10: NON | BL10: NON | BM10: NON | BN10: NON | BO10: NON | BP10: NON | BQ10: NON | BR10: NON | BS10: NON | BT10: NON | BU10: NON | BV10: NON | BW10: NON | BX10: NON | BY10: NON | BZ10: NON | CA10: NON | CB10: NON | CC10: NON | CD10: NON | CE10: NON | CF10: NON | CG10: NON | CH10: NON | CI10: NON | CJ10: NON | CK10: NON | CL10: NON | CM10: NON | CN10: NON | CO10: NON | CP10: NON | CQ10: NON | CR10: NON | CS10: NON | CT10: NON | CU10: NON | CV10: NON | CW10: NON | CX10: NON | CY10: NON | CZ10: NON | DA10: NON | DB10: NON | DC10: NON | DD10: NON | DE10: NON | DF10: NON | DG10: NON | DH10: NON | DI10: NON | DJ10: NON | DK10: NON | DL10: NON | DM10: NON | DN10: NON | DO10: NON | DP10: NON | DQ10: NON | DR10: NON | DS10: NON | DT10: NON | DU10: NON | DV10: NON | DW10: NON
A11: 8 | B11: Mandu, à Wawo, épouse Mbakom | C11: 696112432 | D11: foumbot | E11: 10.636548 | F11: 5.502894 | G11: 100 | H11: en moyenne 5 poulets par jour | I11: NON | J11: 6000000 | K11: Volaile de chair | L11: vente de poulet | M11: 3 | N11: OUI | O11: OUI | P11: NON | Q11: NON | R11: NON | S11: NON | T11: NON | U11: NON | V11: OUI | W11: NON | X11: OUI | Y11: OUI | Z11: OUI | AA11: NON | AB11: NON | AC11: NON | AD11: NON | AE11: NON | AF11: NON | AG11: NON | AH11: NON | AI11: NON | AJ11: NON | AK11: NON | AL11: NON | AM11: NON | AN11: OUI | AO11: OUI | AP11: OUI | AQ11: OUI | AR11: OUI | AS11: NON | AT11: NON | AU11: NON | AV11: NON | AW11: NON | AX11: NON | AY11: NON | AZ11: NON | BA11: NON | BB11: NON | BC11: NON | BD11: NON | BE11: NON | BF11: NON | BG11: NON | BH11: NON | BI11: NON | BJ11: NON | BK11: NON | BL11: NON | BM11: NON | BN11: NON | BO11: NON | BP11: NON | BQ11: NON | BR11: NON | BS11: NON | BT11: NON | BU11: NON | BV11: NON | BW11: NON | BX11: NON | BY11: NON | BZ11: NON | CA11: NON | CB11: NON | CC11: NON | CD11: NON | CE11: NON | CF11: NON | CG11: NON | CH11: NON | CI11: NON | CJ11: NON | CK11: NON | CL11: NON | CM11: NON | CN11: NON | CO11: NON | CP11: NON | CQ11: NON | CR11: NON | CS11: NON | CT11: NON | CU11: NON | CV11: NON | CW11: NON | CX11: NON | CY11: NON | CZ11: NON | DA11: NON | DB11: NON | DC11: NON | DD11: NON | DE11: NON | DF11: NON | DG11: NON | DH11: NON | DI11: NON | DJ11: NON | DK11: NON | DL11: NON | DM11: NON | DN11: NON | DO11: NON | DP11: NON | DQ11: NON | DR11: NON | DS11: NON | DT11: NON | DU11: NON | DV11: NON | DW11: NON
A12: 9 | B12: GROUPE D'INITIATIVE COMMUNE DES PRODUCTEURS ET COMMERCANTS DES FRUITS DU MAYO-DANAY | C12: 698252640 | D12: Caïcaï, dans le quartier Mangal(maroua) | E12: 15.0284567° E | F12: 10.6667589° N | G12: 14 | H12: 200 sacs de goyaves | I12: NON | J12: 4000000 | K12: Fruits et légumes | L12: goyaves | M12: 7 | N12: OUI | O12: NON | P12: NON | Q12: NON | R12: NON | S12: NON | T12: NON | U12: NON | V12: NON | W12: NON | X12: NON | Y12: NON | Z12: NON | AA12: NON | AB12: NON | AC12: NON | AD12: NON | AE12: NON | AF12: NON | AG12: NON | AH12: NON | AI12: NON | AJ12: NON | AK12: NON | AL12: NON | AM12: NON | AN12: NON | AO12: NON | AP12: NON | AQ12: NON | AR12: NON | AS12: NON | AT12: NON | AU12: NON | AV12: NON | AW12: NON | AX12: NON | AY12: NON | AZ12: NON | BA12: NON | BB12: NON | BC12: NON | BD12: NON | BE12: NON | BF12: NON | BG12: NON | BH12: NON | BI12: NON | BJ12: NON | BK12: NON | BL12: NON | BM12: NON | BN12: NON | BO12: NON | BP12: NON | BQ12: NON | BR12: NON | BS12: NON | BT12: NON | BU12: NON | BV12: NON | BW12: NON | BX12: NON | BY12: NON | BZ12: NON | CA12: NON | CB12: NON | CC12: NON | CD12: NON | CE12: NON | CF12: NON | CG12: NON | CH12: NON | CI12: NON | CJ12: NON | CK12: NON | CL12: NON | CM12: NON | CN12: OUI | CO12: OUI | CP12: OUI | CQ12: OUI | CR12: OUI | CS12: NON | CT12: OUI | CU12: OUI | CV12: OUI | CW12: OUI | CX12: OUI | CY12: OUI | CZ12: OUI | DA12: OUI | DB12: OUI | DC12: OUI | DD12: OUI | DE12: OUI | DF12: NON | DG12: NON | DH12: NON | DI12: NON | DJ12: NON | DK12: NON | DL12: NON | DM12: NON | DN12: NON | DO12: NON | DP12: NON | DQ12: NON | DR12: NON | DS12: NON | DT12: NON | DU12: NON | DV12: NON | DW12: NON | DX12: n
A13: 10 | B13: SCOOPS PROD. MAÏS ET OIGNONS KOZA | C13: 696676662 | D13: Caïcaï, dans le quartier Mangal(maroua) | E13: 15.0284567° E | F13: 10.6667589° N | G13: 33 | H13: 80 tonne par an | I13: NON | J13: 45000000 | K13: Fruits et légumes | L13: maïs et l'oignon. | M13: 11 | N13: OUI | O13: NON | P13: NON | Q13: NON | R13: NON | S13: NON | T13: NON | U13: NON | V13: NON | W13: NON | X13: NON | Y13: NON | Z13: NON | AA13: NON | AB13: NON | AC13: NON | AD13: NON | AE13: NON | AF13: NON | AG13: NON | AH13: NON | AI13: NON | AJ13: NON | AK13: NON | AL13: OUI | AM13: OUI | AN13: NON | AO13: NON | AP13: OUI | AQ13: OUI | AR13: NON | AS13: NON | AT13: NON | AU13: NON | AV13: NON | AW13: OUI | AX13: NON | AY13: NON | AZ13: NON | BA13: NON | BB13: OUI | BC13: OUI | BD13: NON | BE13: NON | BF13: NON | BG13: NON | BH13: NON | BI13: NON | BJ13: NON | BK13: NON | BL13: NON | BM13: NON | BN13: NON | BO13: NON | BP13: NON | BQ13: NON | BR13: NON | BS13: NON | BT13: NON | BU13: NON | BV13: NON | BW13: NON | BX13: NON | BY13: NON | BZ13: NON | CA13: NON | CB13: NON | CC13: NON | CD13: NON | CE13: NON | CF13: NON | CG13: NON | CH13: NON | CI13: NON | CJ13: NON | CK13: NON | CL13: NON | CM13: NON | CN13: NON | CO13: NON | CP13: NON | CQ13: NON | CR13: NON | CS13: NON | CT13: NON | CU13: NON | CV13: NON | CW13: NON | CX13: NON | CY13: NON | CZ13: NON | DA13: NON | DB13: NON | DC13: NON | DD13: NON | DE13: NON | DF13: NON | DG13: NON | DH13: NON | DI13: NON | DJ13: NON | DK13: NON | DL13: NON | DM13: NON | DN13: NON | DO13: NON | DP13: NON | DQ13: NON | DR13: NON | DS13: NON | DT13: NON | DU13: NON | DV13: NON | DW13: NON | DX13: n
A14: 11 | B14: SOCIETE COOPERATIVE AVEC CONSEIL D'ADMINISTRATION DES PRODUCTEURS D'OIGNON DE NGONG | C14: 695245414 | D14: Tamoundé, en allant vers Tukalongo | E14: 13.1833 | F14: 9.01667 | G14: 30 | H14: 528 tonne par an | I14: NON | J14: 50000000 | K14: Fruits et légumes | L14: oignon, mais aussi le riz et les haricots. | M14: 7 | N14: OUI | O14: NON | P14: NON | Q14: NON | R14: NON | S14: NON | T14: NON | U14: NON | V14: NON | W14: NON | X14: NON | Y14: NON | Z14: NON | AA14: NON | AB14: NON | AC14: NON | AD14: NON | AE14: NON | AF14: NON | AG14: NON | AH14: NON | AI14: NON | AJ14: NON | AK14: NON | AL14: OUI | AM14: OUI | AN14: OUI | AO14: OUI | AP14: OUI | AQ14: OUI | AR14: OUI | AS14: OUI | AT14: OUI | AU14: OUI | AV14: OUI | AW14: OUI | AX14: OUI | AY14: OUI | AZ14: OUI | BA14: OUI | BB14: OUI | BC14: OUI | BD14: NON | BE14: NON | BF14: NON | BG14: NON | BH14: NON | BI14: NON | BJ14: NON | BK14: NON | BL14: NON | BM14: NON | BN14: NON | BO14: NON | BP14: NON | BQ14: NON | BR14: NON | BS14: NON | BT14: NON | BU14: NON | BV14: NON | BW14: NON | BX14: NON | BY14: NON | BZ14: NON | CA14: NON | CB14: NON | CC14: NON | CD14: NON | CE14: NON | CF14: NON | CG14: NON | CH14: NON | CI14: NON | CJ14: NON | CK14: NON | CL14: NON | CM14: NON | CN14: NON | CO14: NON | CP14: NON | CQ14: NON | CR14: NON | CS14: NON | CT14: NON | CU14: NON | CV14: NON | CW14: NON | CX14: NON | CY14: NON | CZ14: NON | DA14: NON | DB14: NON | DC14: NON | DD14: NON | DE14: NON | DF14: NON | DG14: NON | DH14: NON | DI14: NON | DJ14: NON | DK14: NON | DL14: NON | DM14: NON | DN14: NON | DO14: NON | DP14: NON | DQ14: NON | DR14: NON | DS14: NON | DT14: NON | DU14: NON | DV14: NON | DW14: NON | DX14: n
A15: 12 | B15: Société des Producteurs d'Oignons | C15: 69000012 | D15: Dockbar, en allant vers Tamoundé | E15: 13.1833 | F15: 9.01667 | G15: 53 | H15: 1700 SACS par an | I15: NON | J15: 35000000 | K15: Fruits et légumes | L15: oignon, mais aussi le riz et les haricots. | M15: 15 | N15: OUI | O15: NON | P15: NON | Q15: NON | R15: NON | S15: NON | T15: NON | U15: NON | V15: NON | W15: NON | X15: NON | Y15: NON | Z15: NON | AA15: NON | AB15: NON | AC15: NON | AD15: NON | AE15: NON | AF15: NON | AG15: NON | AH15: NON | AI15: NON | AJ15: NON | AK15: NON | AL15: NON | AM15: NON | AN15: NON | AO15: NON | AP15: NON | AQ15: NON | AR15: NON | AS15: NON | AT15: NON | AU15: NON | AV15: NON | AW15: NON | AX15: NON | AY15: NON | AZ15: NON | BA15: NON | BB15: NON | BC15: NON | BD15: NON | BE15: NON | BF15: NON | BG15: NON | BH15: NON | BI15: NON | BJ15: NON | BK15: NON | BL15: NON | BM15: NON | BN15: NON | BO15: NON | BP15: NON | BQ15: NON | BR15: NON | BS15: NON | BT15: NON | BU15: NON | BV15: NON | BW15: NON | BX15: NON | BY15: NON | BZ15: NON | CA15: NON | CB15: NON | CC15: NON | CD15: NON | CE15: NON | CF15: NON | CG15: NON | CH15: NON | CI15: NON | CJ15: NON | CK15: NON | CL15: NON | CM15: NON | CN15: NON | CO15: NON | CP15: NON | CQ15: NON | CR15: NON | CS15: NON | CT15: NON | CU15: NON | CV15: NON | CW15: NON | CX15: NON | CY15: NON | CZ15: NON | DA15: NON | DB15: NON | DC15: NON | DD15: NON | DE15: NON | DF15: OUI | DG15: OUI | DH15: OUI | DI15: OUI | DJ15: OUI | DK15: OUI | DL15: OUI | DM15: OUI | DN15: OUI | DO15: OUI | DP15: OUI | DQ15: OUI | DR15: OUI | DS15: OUI | DT15: OUI | DU15: OUI | DV15: OUI | DW15: OUI | DX15: n
A16: 13 | B16: NOPING | C16: 691027853 | D16: DOUALA | E16: 9° 41′ 08″ E | F16: 4° 03′ 05″ N | G16: 2 | H16: 120 / 200 cartons par mois | I16: NON | J16: 36400000 | K16: Volaile de chair | L16: œufs | M16: 3 | N16: OUI | O16: NON | P16: OUI | Q16: NON | R16: NON | S16: NON | T16: NON | U16: NON | V16: OUI | W16: OUI | X16: OUI | Y16: NON | Z16: NON | AA16: NON | AB16: NON | AC16: NON | AD16: NON | AE16: OUI | AF16: OUI | AG16: OUI | AH16: NON | AI16: OUI | AJ16: OUI | AK16: OUI | AL16: OUI | AM16: OUI | AN16: OUI | AO16: NON | AP16: NON | AQ16: OUI | AR16: OUI | AS16: NON | AT16: NON | AU16: NON | AV16: NON | AW16: OUI | AX16: OUI | AY16: OUI | AZ16: OUI | BA16: OUI | BB16: OUI | BC16: OUI | BD16: OUI | BE16: OUI | BF16: OUI | BG16: OUI | BH16: OUI | BI16: NON | BJ16: NON | BK16: NON | BL16: NON | BM16: NON | BN16: OUI | BO16: OUI | BP16: OUI | BQ16: NON | BR16: NON | BS16: OUI | BT16: OUI | BU16: OUI | BV16: OUI | BW16: NON | BX16: OUI | BY16: NON | BZ16: OUI | CA16: OUI | CB16: OUI | CC16: OUI | CD16: NON | CE16: NON | CF16: OUI | CG16: OUI | CH16: OUI | CI16: NON | CJ16: NON | CK16: OUI | CL16: OUI | CM16: OUI | CN16: OUI | CO16: OUI | CP16: OUI | CQ16: NON | CR16: OUI | CS16: OUI | CT16: OUI | CU16: OUI | CV16: NON | CW16: NON | CX16: OUI | CY16: OUI | CZ16: OUI | DA16: NON | DB16: NON | DC16: OUI | DD16: OUI | DE16: OUI | DF16: OUI | DG16: OUI | DH16: OUI | DI16: NON | DJ16: OUI | DK16: OUI | DL16: OUI | DM16: OUI | DN16: NON | DO16: NON | DP16: OUI | DQ16: OUI | DR16: OUI | DS16: NON | DT16: NON | DU16: OUI | DV16: OUI | DW16: OUI | DX16: n
A17: 14 | B17: Sanaga Farms | C17: 699612687 | D17: BAFOUSSAM | E17: 10° 25' 3.32" E | F17: 5° 28' 39.90" N | G17: 20 | H17: 4166 Poulets par mois | I17: NON | J17: 200000000 | K17: Volaile de chair | L17: Poulets de chair | M17: 15 | N17: OUI | O17: OUI | P17: NON | Q17: NON | R17: NON | S17: NON | T17: NON | U17: NON | V17: OUI | W17: OUI | X17: OUI | Y17: NON | Z17: NON | AA17: NON | AB17: NON | AC17: NON | AD17: NON | AE17: OUI | AF17: OUI | AG17: OUI | AH17: NON | AI17: NON | AJ17: OUI | AK17: OUI | AL17: NON | AM17: NON | AN17: OUI | AO17: NON | AP17: NON | AQ17: OUI | AR17: OUI | AS17: OUI | AT17: NON | AU17: NON | AV17: NON | AW17: OUI | AX17: OUI | AY17: OUI | AZ17: OUI | BA17: OUI | BB17: OUI | BC17: OUI | BD17: OUI | BE17: OUI | BF17: OUI | BG17: OUI | BH17: OUI | BI17: NON | BJ17: NON | BK17: NON | BL17: NON | BM17: NON | BN17: OUI | BO17: OUI | BP17: OUI | BQ17: NON | BR17: NON | BS17: OUI | BT17: OUI | BU17: OUI | BV17: OUI | BW17: NON | BX17: OUI | BY17: NON | BZ17: OUI | CA17: OUI | CB17: OUI | CC17: OUI | CD17: NON | CE17: NON | CF17: OUI | CG17: OUI | CH17: OUI | CI17: NON | CJ17: NON | CK17: OUI | CL17: OUI | CM17: OUI | CN17: OUI | CO17: OUI | CP17: OUI | CQ17: NON | CR17: OUI | CS17: OUI | CT17: OUI | CU17: OUI | CV17: NON | CW17: NON | CX17: OUI | CY17: OUI | CZ17: OUI | DA17: NON | DB17: NON | DC17: OUI | DD17: OUI | DE17: OUI | DF17: OUI | DG17: OUI | DH17: OUI | DI17: NON | DJ17: OUI | DK17: OUI | DL17: OUI | DM17: OUI | DN17: NON | DO17: NON | DP17: OUI | DQ17: OUI | DR17: OUI | DS17: NON | DT17: NON | DU17: OUI | DV17: OUI | DW17: OUI | DX17: n
A18: 15 | B18: Madame Saïz épouse Wemny | C18: 677766234 / 696606480 | D18: Yaoundé et à Ebolowa | E18: 11° 08' 60.00" E | F18: 2° 54' 59.99" N | G18: Entre 10 et 20 | H18: 4000 | I18: NON | J18: 2500000 | K18: Volaile de chair | L18: Élevage de poulets, poussins, aliments pour nourrir la volaille | M18: 5 | N18: OUI | O18: NON | P18: NON | Q18: NON | R18: NON | S18: NON | T18: NON | U18: NON | V18: NON | W18: NON | X18: NON | Y18: NON | Z18: NON | AA18: OUI | AB18: OUI | AC18: NON | AD18: NON | AE18: OUI | AF18: OUI | AG18: OUI | AH18: OUI | AI18: OUI | AJ18: OUI | AK18: OUI | AL18: NON | AM18: NON | AN18: NON | AO18: NON | AP18: NON | AQ18: NON | AR18: NON | AS18: NON | AT18: NON | AU18: NON | AV18: NON | AW18: NON | AX18: NON | AY18: NON | AZ18: NON | BA18: NON | BB18: NON | BC18: NON | BD18: NON | BE18: NON | BF18: NON | BG18: NON | BH18: NON | BI18: NON | BJ18: NON | BK18: NON | BL18: NON | BM18: NON | BN18: NON | BO18: NON | BP18: NON | BQ18: NON | BR18: NON | BS18: NON | BT18: NON | BU18: NON | BV18: NON | BW18: NON | BX18: NON | BY18: NON | BZ18: NON | CA18: NON | CB18: NON | CC18: NON | CD18: NON | CE18: NON | CF18: NON | CG18: NON | CH18: NON | CI18: NON | CJ18: NON | CK18: NON | CL18: NON | CM18: NON | CN18: NON | CO18: NON | CP18: NON | CQ18: NON | CR18: NON | CS18: NON | CT18: NON | CU18: NON | CV18: NON | CW18: NON | CX18: NON | CY18: NON | CZ18: NON | DA18: NON | DB18: NON | DC18: NON | DD18: NON | DE18: NON | DF18: NON | DG18: NON | DH18: NON | DI18: NON | DJ18: NON | DK18: NON | DL18: NON | DM18: NON | DN18: NON | DO18: NON | DP18: NON | DQ18: NON | DR18: NON | DS18: NON | DT18: NON | DU18: NON | DV18: NON | DW18: NON | DX18: n
A19: 16 | B19: Coopérative d'éleveurs de canards et de poulets de Bupindi | C19: 674853303 | D19: Bipindi | E19: 10° 24' 59.99" E | F19: 3° 04' 60.00" N | G19: 10 | H19: 500 | I19: NON | J19: 3000000 | K19: Volaile de chair | L19: Élevage de canards et de poulets | M19: 5 | N19: OUI | O19: NON | P19: NON | Q19: NON | R19: NON | S19: NON | T19: NON | U19: NON | V19: NON | W19: NON | X19: NON | Y19: NON | Z19: NON | AA19: NON | AB19: OUI | AC19: NON | AD19: NON | AE19: OUI | AF19: OUI | AG19: OUI | AH19: OUI | AI19: OUI | AJ19: OUI | AK19: OUI | AL19: NON | AM19: NON | AN19: NON | AO19: NON | AP19: NON | AQ19: NON | AR19: NON | AS19: NON | AT19: NON | AU19: NON | AV19: NON | AW19: NON | AX19: NON | AY19: NON | AZ19: NON | BA19: NON | BB19: NON | BC19: NON | BD19: NON | BE19: NON | BF19: NON | BG19: NON | BH19: NON | BI19: NON | BJ19: NON | BK19: NON | BL19: NON | BM19: NON | BN19: NON | BO19: NON | BP19: NON | BQ19: NON | BR19: NON | BS19: NON | BT19: NON | BU19: NON | BV19: NON | BW19: NON | BX19: NON | BY19: NON | BZ19: NON | CA19: NON | CB19: NON | CC19: NON | CD19: NON | CE19: NON | CF19: NON | CG19: NON | CH19: NON | CI19: NON | CJ19: NON | CK19: NON | CL19: NON | CM19: NON | CN19: NON | CO19: NON | CP19: NON | CQ19: NON | CR19: NON | CS19: NON | CT19: NON | CU19: NON | CV19: NON | CW19: NON | CX19: NON | CY19: NON | CZ19: NON | DA19: NON | DB19: NON | DC19: NON | DD19: NON | DE19: NON | DF19: NON | DG19: NON | DH19: NON | DI19: NON | DJ19: NON | DK19: NON | DL19: NON | DM19: NON | DN19: NON | DO19: NON | DP19: NON | DQ19: NON | DR19: NON | DS19: NON | DT19: NON | DU19: NON | DV19: NON | DW19: NON | DX19: n
A20: 17 | B20: TIOMELA CLOTILDE | C20: 675151364 | D20: foumbot | E20: 10.636548 | F20: 5.502894 | G20: 5 | H20: 400 | I20: NON | J20: 6000000 | K20: Volaile de chair | L20: vente de poulet | M20: 5 | N20: OUI | O20: OUI | P20: OUI | Q20: OUI | R20: OUI | S20: OUI | T20: NON | U20: NON | V20: NON | W20: NON | X20: NON | Y20: NON | Z20: NON | AA20: NON | AB20: NON | AC20: NON | AD20: NON | AE20: NON | AF20: NON | AG20: NON | AH20: NON | AI20: NON | AJ20: NON | AK20: NON | AL20: NON | AM20: NON | AN20: NON | AO20: NON | AP20: NON | AQ20: NON | AR20: NON | AS20: NON | AT20: NON | AU20: NON | AV20: NON | AW20: NON | AX20: NON | AY20: NON | AZ20: NON | BA20: NON | BB20: NON | BC20: NON | BD20: NON | BE20: NON | BF20: NON | BG20: NON | BH20: NON | BI20: NON | BJ20: NON | BK20: NON | BL20: NON | BM20: NON | BN20: NON | BO20: NON | BP20: NON | BQ20: NON | BR20: NON | BS20: NON | BT20: NON | BU20: NON | BV20: NON | BW20: NON | BX20: NON | BY20: NON | BZ20: NON | CA20: NON | CB20: NON | CC20: NON | CD20: NON | CE20: NON | CF20: NON | CG20: NON | CH20: NON | CI20: NON | CJ20: NON | CK20: NON | CL20: NON | CM20: NON | CN20: OUI | CO20: OUI | CP20: OUI | CQ20: OUI | CR20: OUI | CS20: OUI | CT20: OUI | CU20: OUI | CV20: OUI | CW20: OUI | CX20: OUI | CY20: OUI | CZ20: OUI | DA20: OUI | DB20: OUI | DC20: OUI | DD20: OUI | DE20: OUI | DF20: OUI | DG20: OUI | DH20: OUI | DI20: OUI | DJ20: OUI | DK20: OUI | DL20: OUI | DM20: OUI | DN20: OUI | DO20: OUI | DP20: OUI | DQ20: OUI | DR20: OUI | DS20: OUI | DT20: OUI | DU20: OUI | DV20: OUI | DW20: OUI
A21: 18 | B21: GROUPE D'INITIATIVE COMMUNE DE FABRICATION NATURELLE DE YAOURT DU LITTORAL CENTRE | C21: 699788027 | D21: Littoral | G21: 8 | H21: 300 | I21: NON | J21: 4000000 | K21: Lait | L21: Lait | M21: 22 | N21: OUI | O21: OUI | P21: NON | Q21: NON | R21: NON | S21: NON | T21: NON | U21: NON | V21: NON | W21: NON | X21: NON | Y21: NON | Z21: NON | AA21: NON | AB21: NON | AC21: NON | AD21: NON | AE21: NON | AF21: NON | AG21: NON | AH21: NON | AI21: NON | AJ21: NON | AK21: NON | AL21: OUI | AM21: OUI | AN21: NON | AO21: NON | AP21: NON | AQ21: OUI | AR21: OUI | AS21: OUI | AT21: OUI | AU21: OUI | AV21: OUI | AW21: OUI | AX21: OUI | AY21: OUI | AZ21: OUI | BA21: OUI | BB21: OUI | BC21: OUI | BD21: NON | BE21: NON | BF21: NON | BG21: NON | BH21: NON | BI21: NON | BJ21: NON | BK21: NON | BL21: NON | BM21: NON | BN21: NON | BO21: NON | BP21: NON | BQ21: NON | BR21: NON | BS21: NON | BT21: NON | BU21: NON | BV21: NON | BW21: NON | BX21: NON | BY21: NON | BZ21: NON | CA21: NON | CB21: NON | CC21: NON | CD21: NON | CE21: NON | CF21: NON | CG21: NON | CH21: NON | CI21: NON | CJ21: NON | CK21: NON | CL21: NON | CM21: NON | CN21: NON | CO21: NON | CP21: NON | CQ21: NON | CR21: NON | CS21: NON | CT21: NON | CU21: NON | CV21: NON | CW21: NON | CX21: NON | CY21: NON | CZ21: NON | DA21: NON | DB21: NON | DC21: NON | DD21: NON | DE21: NON | DF21: NON | DG21: NON | DH21: NON | DI21: NON | DJ21: NON | DK21: NON | DL21: NON | DM21: NON | DN21: NON | DO21: NON | DP21: NON | DQ21: NON | DR21: NON | DS21: NON | DT21: NON | DU21: NON | DV21: NON | DW21: NON
A22: 19 | B22: GIC DES PRODUCTRICES DE MANIOC | C22: 678227820 | D22: Littoral | G22: 5 | H22: 20 tonnes | I22: NON | J22: 2000000 | K22: Manioc et autres tubercules | L22: Manioc | M22: 5 | N22: OUI | O22: NON | P22: NON | Q22: NON | R22: NON | S22: NON | T22: NON | U22: NON | V22: NON | W22: NON | X22: NON | Y22: NON | Z22: NON | AA22: NON | AB22: NON | AC22: NON | AD22: NON | AE22: NON | AF22: NON | AG22: NON | AH22: NON | AI22: NON | AJ22: NON | AK22: NON | AL22: NON | AM22: NON | AN22: NON | AO22: NON | AP22: NON | AQ22: NON | AR22: NON | AS22: NON | AT22: NON | AU22: NON | AV22: NON | AW22: NON | AX22: NON | AY22: NON | AZ22: NON | BA22: NON | BB22: NON | BC22: NON | BD22: NON | BE22: NON | BF22: NON | BG22: NON | BH22: NON | BI22: NON | BJ22: NON | BK22: NON | BL22: NON | BM22: NON | BN22: NON | BO22: NON | BP22: NON | BQ22: NON | BR22: NON | BS22: NON | BT22: NON | BU22: NON | BV22: NON | BW22: NON | BX22: NON | BY22: NON | BZ22: NON | CA22: NON | CB22: NON | CC22: NON | CD22: NON | CE22: NON | CF22: NON | CG22: NON | CH22: NON | CI22: NON | CJ22: NON | CK22: NON | CL22: NON | CM22: NON | CN22: OUI | CO22: OUI | CP22: NON | CQ22: OUI | CR22: OUI | CS22: NON | CT22: OUI | CU22: OUI | CV22: OUI | CW22: OUI | CX22: OUI | CY22: OUI | CZ22: OUI | DA22: OUI | DB22: OUI | DC22: OUI | DD22: OUI | DE22: OUI | DF22: OUI | DG22: OUI | DH22: NON | DI22: OUI | DJ22: OUI | DK22: NON | DL22: OUI | DM22: OUI | DN22: OUI | DO22: OUI | DP22: OUI | DQ22: OUI | DR22: OUI | DS22: OUI | DT22: OUI | DU22: OUI | DV22: OUI | DW22: OUI
A23: 20 | B23: LYCEE DE GARI-GOMBO | C23: 651942556 | D23: Littoral | G23: 4 | H23: 30 sacs de 100 kg | I23: OUI | J23: 1500000 | K23: Manioc et autres tubercules | L23: Manioc | M23: 7 | N23: OUI | O23: NON | P23: NON | Q23: NON | R23: NON | S23: NON | T23: NON | U23: NON | V23: NON | W23: NON | X23: NON | Y23: NON | Z23: NON | AA23: NON | AB23: NON | AC23: NON | AD23: NON | AE23: NON | AF23: NON | AG23: NON | AH23: NON | AI23: NON | AJ23: NON | AK23: NON | AL23: NON | AM23: NON | AN23: NON | AO23: NON | AP23: NON | AQ23: NON | AR23: NON | AS23: NON | AT23: NON | AU23: NON | AV23: NON | AW23: NON | AX23: NON | AY23: NON | AZ23: NON | BA23: NON | BB23: NON | BC23: NON | BD23: NON | BE23: NON | BF23: NON | BG23: NON | BH23: NON | BI23: NON | BJ23: NON | BK23: NON | BL23: NON | BM23: NON | BN23: NON | BO23: NON | BP23: NON | BQ23: NON | BR23: NON | BS23: NON | BT23: NON | BU23: NON | BV23: NON | BW23: NON | BX23: NON | BY23: NON | BZ23: NON | CA23: NON | CB23: NON | CC23: NON | CD23: NON | CE23: NON | CF23: NON | CG23: NON | CH23: NON | CI23: NON | CJ23: NON | CK23: NON | CL23: NON | CM23: NON | CN23: OUI | CO23: OUI | CP23: OUI | CQ23: OUI | CR23: OUI | CS23: OUI | CT23: OUI | CU23: OUI | CV23: OUI | CW23: OUI | CX23: OUI | CY23: OUI | CZ23: OUI | DA23: OUI | DB23: OUI | DC23: OUI | DD23: OUI | DE23: OUI | DF23: NON | DG23: NON | DH23: NON | DI23: NON | DJ23: NON | DK23: NON | DL23: NON | DM23: NON | DN23: NON | DO23: NON | DP23: NON | DQ23: NON | DR23: NON | DS23: NON | DT23: NON | DU23: NON | DV23: NON | DW23: NON
A24: 21 | B24: SOCIETE COOPERATIVE AVEC CONSEIL D'ADMINISTRATION AGROPASTORALE DES ACTEURS DU DEVELOPPEMENT DE NITOUKOU | C24: 677750389 | D24: Tshukou, | G24: 6 | H24: 1200 tonne par an | I24: NON | J24: 6000000 | K24: Manioc et autres tubercules | L24: Manioc | M24: 2 | N24: OUI | O24: NON | P24: NON | Q24: NON | R24: NON | S24: NON | T24: NON | U24: NON | V24: NON | W24: NON | X24: NON | Y24: NON | Z24: NON | AA24: NON | AB24: NON | AC24: NON | AD24: NON | AE24: NON | AF24: NON | AG24: NON | AH24: NON | AI24: NON | AJ24: NON | AK24: NON | AL24: NON | AM24: NON | AN24: NON | AO24: NON | AP24: NON | AQ24: NON | AR24: NON | AS24: NON | AT24: NON | AU24: NON | AV24: NON | AW24: NON | AX24: NON | AY24: NON | AZ24: NON | BA24: NON | BB24: NON | BC24: NON | BD24: NON | BE24: NON | BF24: NON | BG24: NON | BH24: NON | BI24: NON | BJ24: NON | BK24: NON | BL24: NON | BM24: NON | BN24: NON | BO24: NON | BP24: NON | BQ24: NON | BR24: NON | BS24: NON | BT24: NON | BU24: NON | BV24: NON | BW24: NON | BX24: NON | BY24: NON | BZ24: NON | CA24: NON | CB24: NON | CC24: NON | CD24: NON | CE24: NON | CF24: NON | CG24: NON | CH24: NON | CI24: NON | CJ24: NON | CK24: NON | CL24: NON | CM24: NON | CN24: OUI | CO24: OUI | CP24: OUI | CQ24: OUI | CR24: OUI | CS24: OUI | CT24: OUI | CU24: OUI | CV24: OUI | CW24: OUI | CX24: OUI | CY24: OUI | CZ24: OUI | DA24: OUI | DB24: OUI | DC24: OUI | DD24: OUI | DE24: OUI | DF24: OUI | DG24: OUI | DH24: OUI | DI24: OUI | DJ24: OUI | DK24: OUI | DL24: OUI | DM24: OUI | DN24: OUI | DO24: OUI | DP24: OUI | DQ24: OUI | DR24: OUI | DS24: OUI | DT24: OUI | DU24: OUI | DV24: OUI | DW24: OUI
A25: 22 | B25: Groupe Initiatives Communes Agropastoral | C25: 677-76-6234 / 696-60-6480 | D25: FOUMBOT | G25: 15 | H25: 1000 TONNE | I25: NON | J25: 5000000 | K25: Manioc et autres tubercules | L25: manioc | M25: 3 | N25: OUI | O25: NON | P25: NON | Q25: NON | R25: NON | S25: NON | T25: NON | U25: NON | V25: NON | W25: NON | X25: NON | Y25: NON | Z25: NON | AA25: OUI | AB25: OUI | AC25: OUI | AD25: OUI | AE25: OUI | AF25: OUI | AG25: OUI | AH25: OUI | AI25: OUI | AJ25: OUI | AK25: OUI | AL25: OUI | AM25: OUI | AN25: OUI | AO25: NON | AP25: NON | AQ25: OUI | AR25: OUI | AS25: NON | AT25: NON | AU25: NON | AV25: NON | AW25: OUI | AX25: OUI | AY25: OUI | AZ25: OUI | BA25: OUI | BB25: OUI | BC25: OUI | BD25: OUI | BE25: OUI | BF25: OUI | BG25: OUI | BH25: OUI | BI25: NON | BJ25: NON | BK25: NON | BL25: NON | BM25: NON | BN25: OUI | BO25: OUI | BP25: OUI | BQ25: NON | BR25: NON | BS25: OUI | BT25: OUI | BU25: OUI | BV25: OUI | BW25: NON | BX25: OUI | BY25: NON | BZ25: OUI | CA25: OUI | CB25: OUI | CC25: OUI | CD25: NON | CE25: NON | CF25: OUI | CG25: OUI | CH25: OUI | CI25: NON | CJ25: NON | CK25: OUI | CL25: OUI | CM25: OUI | CN25: OUI | CO25: OUI | CP25: OUI | CQ25: NON | CR25: OUI | CS25: OUI | CT25: OUI | CU25: OUI | CV25: NON | CW25: NON | CX25: OUI | CY25: OUI | CZ25: OUI | DA25: NON | DB25: NON | DC25: OUI | DD25: OUI | DE25: OUI | DF25: OUI | DG25: OUI | DH25: OUI | DI25: NON | DJ25: OUI | DK25: OUI | DL25: OUI | DM25: OUI | DN25: NON | DO25: NON | DP25: OUI | DQ25: OUI | DR25: OUI | DS25: NON | DT25: NON | DU25: OUI | DV25: OUI | DW25: OUI | DX25: n
A26: 23 | B26: SOCIETE COOPERATIVE SIMPLIFIEE RECOLTE 237 FERME NKOUE | C26: 690767345 | D26: Yaoundé | G26: 3 | H26: 2600 alevin par an | I26: NON | J26: 700000 | K26: Poisson | L26: cilliure | M26: 1 | N26: OUI | O26: OUI | P26: NON | Q26: NON | R26: NON | S26: NON | T26: NON | U26: NON | V26: NON | W26: NON | X26: NON | Y26: NON | Z26: NON | AA26: NON | AB26: NON | AC26: NON | AD26: NON | AE26: NON | AF26: NON | AG26: NON | AH26: NON | AI26: NON | AJ26: NON | AK26: NON | AL26: NON | AM26: NON | AN26: NON | AO26: NON | AP26: NON | AQ26: NON | AR26: NON | AS26: NON | AT26: NON | AU26: NON | AV26: NON | AW26: NON | AX26: NON | AY26: NON | AZ26: NON | BA26: NON | BB26: NON | BC26: NON | BD26: OUI | BE26: OUI | BF26: NON | BG26: NON | BH26: NON | BI26: OUI | BJ26: OUI | BK26: OUI | BL26: OUI | BM26: OUI | BN26: OUI | BO26: OUI | BP26: OUI | BQ26: OUI | BR26: OUI | BS26: OUI | BT26: OUI | BU26: OUI | BV26: NON | BW26: NON | BX26: NON | BY26: NON | BZ26: NON | CA26: NON | CB26: NON | CC26: NON | CD26: NON | CE26: NON | CF26: NON | CG26: NON | CH26: NON | CI26: NON | CJ26: NON | CK26: NON | CL26: NON | CM26: NON | CN26: NON | CO26: NON | CP26: NON | CQ26: NON | CR26: NON | CS26: NON | CT26: NON | CU26: NON | CV26: NON | CW26: NON | CX26: NON | CY26: NON | CZ26: NON | DA26: NON | DB26: NON | DC26: NON | DD26: NON | DE26: NON | DF26: NON | DG26: NON | DH26: NON | DI26: NON | DJ26: NON | DK26: NON | DL26: NON | DM26: NON | DN26: NON | DO26: NON | DP26: NON | DQ26: NON | DR26: NON | DS26: NON | DT26: NON | DU26: NON | DV26: NON | DW26: NON
A27: 24 | B27: SOCIÉTÉ COOPERATIVE SIMPLIFIEE DES PRODUCTEURS DE PATATE DE BONJONG | C27: 697324852 | D27: Adamaoua | G27: 14 | H27: 50 tonnes par mois | I27: NON | J27: 500000 | K27: Manioc et autres tubercules | L27: Patates douces | M27: 5 | N27: OUI | O27: NON | P27: NON | Q27: NON | R27: NON | S27: NON | T27: NON | U27: NON | V27: NON | W27: NON | X27: NON | Y27: NON | Z27: NON | AA27: NON | AB27: NON | AC27: NON | AD27: NON | AE27: NON | AF27: NON | AG27: NON | AH27: NON | AI27: NON | AJ27: NON | AK27: NON | AL27: OUI | AM27: OUI | AN27: OUI | AO27: OUI | AP27: OUI | AQ27: OUI | AR27: NON | AS27: NON | AT27: NON | AU27: NON | AV27: NON | AW27: NON | AX27: NON | AY27: OUI | AZ27: NON | BA27: NON | BB27: OUI | BC27: OUI | BD27: NON | BE27: NON | BF27: NON | BG27: NON | BH27: NON | BI27: NON | BJ27: NON | BK27: NON | BL27: NON | BM27: NON | BN27: NON | BO27: NON | BP27: NON | BQ27: NON | BR27: NON | BS27: NON | BT27: NON | BU27: NON | BV27: NON | BW27: NON | BX27: NON | BY27: NON | BZ27: NON | CA27: NON | CB27: NON | CC27: NON | CD27: NON | CE27: NON | CF27: NON | CG27: NON | CH27: NON | CI27: NON | CJ27: NON | CK27: NON | CL27: NON | CM27: NON | CN27: OUI | CO27: OUI | CP27: OUI | CQ27: OUI | CR27: OUI | CS27: OUI | CT27: OUI | CU27: OUI | CV27: OUI | CW27: OUI | CX27: OUI | CY27: OUI | CZ27: OUI | DA27: OUI | DB27: OUI | DC27: OUI | DD27: OUI | DE27: OUI | DF27: OUI | DG27: OUI | DH27: OUI | DI27: OUI | DJ27: OUI | DK27: OUI | DL27: OUI | DM27: OUI | DN27: OUI | DO27: OUI | DP27: OUI | DQ27: OUI | DR27: OUI | DS27: OUI | DT27: OUI | DU27: OUI | DV27: OUI | DW27: OUI
A28: 25 | B28: SCOOPS PTASPL | C28: 656102611 | D28: yaoundé | G28: 8 | H28: 1500 kili le mois | I28: NON | J28: 1500000 | K28: Manioc et autres tubercules | L28: Tapioca | M28: 1 | N28: OUI | O28: OUI | P28: NON | Q28: NON | R28: NON | S28: NON | T28: NON | U28: NON | V28: NON | W28: NON | X28: NON | Y28: NON | Z28: NON | AA28: NON | AB28: NON | AC28: NON | AD28: NON | AE28: NON | AF28: NON | AG28: NON | AH28: NON | AI28: NON | AJ28: NON | AK28: NON | AL28: OUI | AM28: NON | AN28: OUI | AO28: OUI | AP28: OUI | AQ28: OUI | AR28: OUI | AS28: NON | AT28: NON | AU28: NON | AV28: NON | AW28: NON | AX28: OUI | AY28: OUI | AZ28: OUI | BA28: OUI | BB28: OUI | BC28: OUI | BD28: NON | BE28: NON | BF28: NON | BG28: NON | BH28: NON | BI28: NON | BJ28: NON | BK28: NON | BL28: NON | BM28: NON | BN28: NON | BO28: NON | BP28: NON | BQ28: NON | BR28: NON | BS28: NON | BT28: NON | BU28: NON | BV28: NON | BW28: NON | BX28: NON | BY28: NON | BZ28: NON | CA28: NON | CB28: NON | CC28: NON | CD28: NON | CE28: NON | CF28: NON | CG28: NON | CH28: NON | CI28: NON | CJ28: NON | CK28: NON | CL28: NON | CM28: NON | CN28: NON | CO28: NON | CP28: NON | CQ28: NON | CR28: NON | CS28: NON | CT28: NON | CU28: NON | CV28: NON | CW28: NON | CX28: NON | CY28: NON | CZ28: NON | DA28: NON | DB28: NON | DC28: NON | DD28: NON | DE28: NON | DF28: NON | DG28: NON | DH28: NON | DI28: NON | DJ28: NON | DK28: NON | DL28: NON | DM28: NON | DN28: NON | DO28: NON | DP28: NON | DQ28: NON | DR28: NON | DS28: NON | DT28: NON | DU28: NON | DV28: NON | DW28: NON
A29: 26 | B29: SOCIETE COOPERATIVE AVEC CONSEIL D'ADMINISTRATION DES PRODUCTEURS DE MANIOC WARACK MADIKOUM | C29: 696492700 | D29: Adamaoua | G29: 10 | H29: 80 SACS PAR MOIS | I29: NON | J29: 10500000 | K29: Manioc et autres tubercules | L29: Manioc | M29: 8 | N29: OUI | O29: NON | P29: NON | Q29: NON | R29: NON | S29: NON | T29: NON | U29: NON | V29: NON | W29: NON | X29: NON | Y29: NON | Z29: NON | AA29: NON | AB29: NON | AC29: NON | AD29: NON | AE29: NON | AF29: NON | AG29: NON | AH29: NON | AI29: NON | AJ29: NON | AK29: NON | AL29: NON | AM29: NON | AN29: NON | AO29: NON | AP29: NON | AQ29: NON | AR29: NON | AS29: NON | AT29: NON | AU29: NON | AV29: NON | AW29: NON | AX29: NON | AY29: NON | AZ29: NON | BA29: NON | BB29: NON | BC29: NON | BD29: OUI | BE29: OUI | BF29: OUI | BG29: OUI | BH29: OUI | BI29: OUI | BJ29: OUI | BK29: OUI | BL29: OUI | BM29: OUI | BN29: OUI | BO29: OUI | BP29: OUI | BQ29: OUI | BR29: OUI | BS29: OUI | BT29: OUI | BU29: OUI | BV29: NON | BW29: NON | BX29: NON | BY29: NON | BZ29: NON | CA29: NON | CB29: NON | CC29: NON | CD29: NON | CE29: NON | CF29: NON | CG29: NON | CH29: NON | CI29: NON | CJ29: NON | CK29: NON | CL29: NON | CM29: NON | CN29: NON | CO29: NON | CP29: NON | CQ29: NON | CR29: NON | CS29: NON | CT29: NON | CU29: NON | CV29: NON | CW29: NON | CX29: NON | CY29: NON | CZ29: NON | DA29: NON | DB29: NON | DC29: NON | DD29: NON | DE29: NON | DF29: NON | DG29: NON | DH29: NON | DI29: NON | DJ29: NON | DK29: NON | DL29: NON | DM29: NON | DN29: NON | DO29: NON | DP29: NON | DQ29: NON | DR29: NON | DS29: NON | DT29: NON | DU29: NON | DV29: NON | DW29: NON
A30: 27 | B30: Leprince | C30: 698843700 | G30: 25 | H30: 400 litre par semaines | I30: NON | J30: 4800000 | K30: Huile de palme | L30: Huile de palme | M30: 16 | N30: NON | O30: OUI | P30: NON | Q30: NON | R30: NON | S30: NON | T30: NON | U30: NON | V30: NON | W30: NON | X30: NON | Y30: NON | Z30: NON | AA30: NON | AB30: NON | AC30: NON | AD30: NON | AE30: NON | AF30: NON | AG30: NON | AH30: NON | AI30: NON | AJ30: NON | AK30: NON | AL30: NON | AM30: NON | AN30: NON | AO30: NON | AP30: NON | AQ30: NON | AR30: NON | AS30: NON | AT30: NON | AU30: NON | AV30: NON | AW30: NON | AX30: NON | AY30: NON | AZ30: NON | BA30: NON | BB30: NON | BC30: NON | BD30: NON | BE30: NON | BF30: NON | BG30: NON | BH30: NON | BI30: NON | BJ30: NON | BK30: NON | BL30: NON | BM30: NON | BN30: NON | BO30: NON | BP30: NON | BQ30: NON | BR30: NON | BS30: NON | BT30: NON | BU30: NON | BV30: NON | BW30: NON | BX30: NON | BY30: NON | BZ30: NON | CA30: NON | CB30: NON | CC30: NON | CD30: NON | CE30: NON | CF30: NON | CG30: NON | CH30: NON | CI30: NON | CJ30: NON | CK30: NON | CL30: NON | CM30: NON | CN30: OUI | CO30: OUI | CP30: OUI | CQ30: OUI | CR30: OUI | CS30: OUI | CT30: OUI | CU30: OUI | CV30: OUI | CW30: OUI | CX30: OUI | CY30: OUI | CZ30: OUI | DA30: OUI | DB30: OUI | DC30: OUI | DD30: OUI | DE30: OUI | DF30: NON | DG30: NON | DH30: NON | DI30: NON | DJ30: NON | DK30: NON | DL30: NON | DM30: NON | DN30: NON | DO30: NON | DP30: NON | DQ30: NON | DR30: NON | DS30: NON | DT30: NON | DU30: NON | DV30: NON | DW30: NON
A31: 28 | B31: STE COOP-CA DE PRODUCTION ET TRANSFORMATION DE MANIOC ET ACTIVITÉS CONNEXES DE MBANGASSINA | C31: 675493737 | G31: 10 | H31: 30 tonnes par an | I31: NON | J31: 10000000 | K31: Manioc et autres tubercules | L31: tapioca, l'amidon et les farines | M31: 3 | N31: OUI | O31: NON | P31: NON | Q31: NON | R31: OUI | S31: OUI | T31: NON | U31: NON | V31: NON | W31: NON | X31: NON | Y31: NON | Z31: NON | AA31: NON | AB31: NON | AC31: NON | AD31: NON | AE31: NON | AF31: NON | AG31: NON | AH31: NON | AI31: NON | AJ31: NON | AK31: NON | AL31: NON | AM31: NON | AN31: NON | AO31: NON | AP31: NON | AQ31: NON | AR31: NON | AS31: NON | AT31: NON | AU31: NON | AV31: NON | AW31: NON | AX31: NON | AY31: NON | AZ31: NON | BA31: NON | BB31: NON | BC31: NON | BD31: NON | BE31: NON | BF31: NON | BG31: NON | BH31: NON | BI31: NON | BJ31: NON | BK31: NON | BL31: NON | BM31: NON | BN31: NON | BO31: NON | BP31: NON | BQ31: NON | BR31: NON | BS31: NON | BT31: NON | BU31: NON | BV31: NON | BW31: NON | BX31: NON | BY31: NON | BZ31: NON | CA31: NON | CB31: NON | CC31: NON | CD31: NON | CE31: NON | CF31: NON | CG31: NON | CH31: NON | CI31: NON | CJ31: NON | CK31: NON | CL31: NON | CM31: NON | CN31: OUI | CO31: OUI | CP31: OUI | CQ31: NON | CR31: OUI | CS31: OUI | CT31: OUI | CU31: OUI | CV31: OUI | CW31: OUI | CX31: OUI | CY31: OUI | CZ31: OUI | DA31: OUI | DB31: OUI | DC31: OUI | DD31: OUI | DE31: OUI | DF31: OUI | DG31: OUI | DH31: OUI | DI31: OUI | DJ31: OUI | DK31: OUI | DL31: OUI | DM31: OUI | DN31: OUI | DO31: OUI | DP31: OUI | DQ31: OUI | DR31: OUI | DS31: OUI | DT31: OUI | DU31: OUI | DV31: OUI | DW31: OUI
A32: 29 | B32: SOCIETE COOPÉRATIVE AVEC CONSEIL D'ADMINISTRATION DES PRODUCTEURS DE MANIOC SAPE DE BERTOUA | C32: 691977154 | D32: Bertoua | G32: 20 | H32: 60 tonnes par an | I32: NON | J32: 3000000 | K32: Manioc et autres tubercules | L32: Manioc | M32: 4 | N32: OUI | O32: NON | P32: NON | Q32: NON | R32: NON | S32: NON | T32: NON | U32: NON | V32: NON | W32: NON | X32: NON | Y32: NON | Z32: NON | AA32: NON | AB32: NON | AC32: NON | AD32: NON | AE32: NON | AF32: NON | AG32: NON | AH32: NON | AI32: NON | AJ32: NON | AK32: NON | AL32: OUI | AM32: OUI | AN32: OUI | AO32: OUI | AP32: OUI | AQ32: OUI | AR32: OUI | AS32: OUI | AT32: OUI | AU32: OUI | AV32: OUI | AW32: OUI | AX32: OUI | AY32: OUI | AZ32: OUI | BA32: OUI | BB32: OUI | BC32: OUI | BD32: NON | BE32: NON | BF32: NON | BG32: NON | BH32: NON | BI32: NON | BJ32: NON | BK32: NON | BL32: NON | BM32: NON | BN32: NON | BO32: NON | BP32: NON | BQ32: NON | BR32: NON | BS32: NON | BT32: NON | BU32: NON | BV32: NON | BW32: NON | BX32: NON | BY32: NON | BZ32: NON | CA32: NON | CB32: NON | CC32: NON | CD32: NON | CE32: NON | CF32: NON | CG32: NON | CH32: NON | CI32: NON | CJ32: NON | CK32: NON | CL32: NON | CM32: NON | CN32: NON | CO32: NON | CP32: NON | CQ32: NON | CR32: NON | CS32: NON | CT32: NON | CU32: NON | CV32: NON | CW32: NON | CX32: NON | CY32: NON | CZ32: NON | DA32: NON | DB32: NON | DC32: NON | DD32: NON | DE32: NON | DF32: OUI | DG32: OUI | DH32: OUI | DI32: OUI | DJ32: OUI | DK32: OUI | DL32: OUI | DM32: OUI | DN32: OUI | DO32: OUI | DP32: OUI | DQ32: OUI | DR32: OUI | DS32: OUI | DT32: OUI | DU32: OUI | DV32: OUI | DW32: OUI
A33: 30 | B33: coopacam - | C33: 699814462 | D33: MFOU | G33: 10 | H33: 500L par semaine | I33: NON | J33: 25000000 | K33: Huile de palme | L33: l'huile de palme brut | M33: 17 | N33: OUI | O33: OUI | P33: NON | Q33: NON | R33: NON | S33: NON | T33: NON | U33: NON | V33: NON | W33: NON | X33: NON | Y33: NON | Z33: NON | AA33: NON | AB33: NON | AC33: NON | AD33: NON | AE33: NON | AF33: NON | AG33: NON | AH33: NON | AI33: NON | AJ33: NON | AK33: NON | AL33: NON | AM33: NON | AN33: NON | AO33: NON | AP33: NON | AQ33: NON | AR33: NON | AS33: NON | AT33: NON | AU33: NON | AV33: NON | AW33: NON | AX33: NON | AY33: NON | AZ33: NON | BA33: NON | BB33: NON | BC33: NON | BD33: NON | BE33: NON | BF33: NON | BG33: NON | BH33: NON | BI33: NON | BJ33: NON | BK33: NON | BL33: NON | BM33: NON | BN33: NON | BO33: NON | BP33: NON | BQ33: NON | BR33: NON | BS33: NON | BT33: NON | BU33: NON | BV33: NON | BW33: NON | BX33: NON | BY33: NON | BZ33: NON | CA33: NON | CB33: NON | CC33: NON | CD33: NON | CE33: NON | CF33: NON | CG33: NON | CH33: NON | CI33: NON | CJ33: NON | CK33: NON | CL33: NON | CM33: NON | CN33: OUI | CO33: OUI | CP33: OUI | CQ33: OUI | CR33: OUI | CS33: OUI | CT33: OUI | CU33: OUI | CV33: OUI | CW33: OUI | CX33: OUI | CY33: OUI | CZ33: OUI | DA33: OUI | DB33: OUI | DC33: OUI | DD33: OUI | DE33: OUI | DF33: NON | DG33: NON | DH33: NON | DI33: NON | DJ33: NON | DK33: NON | DL33: NON | DM33: NON | DN33: NON | DO33: NON | DP33: NON | DQ33: NON | DR33: NON | DS33: NON | DT33: NON | DU33: NON | DV33: NON | DW33: NON
A34: 31 | B34: SCOOP MAN DE MBALMAYO | C34: 696819231 | D34: Mbalmayo | G34: 25 | H34: 875 tonne par Saison | I34: NON | J34: 3600000 | K34: Manioc et autres tubercules | L34: manioc et dans la transformation du manioc en amidon | M34: 20 | N34: OUI | O34: NON | P34: NON | Q34: NON | R34: NON | S34: NON | T34: NON | U34: NON | V34: NON | W34: NON | X34: NON | Y34: NON | Z34: NON | AA34: NON | AB34: NON | AC34: NON | AD34: NON | AE34: NON | AF34: NON | AG34: NON | AH34: NON | AI34: NON | AJ34: NON | AK34: NON | AL34: OUI | AM34: OUI | AN34: OUI | AO34: OUI | AP34: OUI | AQ34: OUI | AR34: OUI | AS34: OUI | AT34: OUI | AU34: OUI | AV34: OUI | AW34: OUI | AX34: OUI | AY34: OUI | AZ34: OUI | BA34: OUI | BB34: OUI | BC34: OUI | BD34: OUI | BE34: OUI | BF34: OUI | BG34: OUI | BH34: OUI | BI34: OUI | BJ34: OUI | BK34: OUI | BL34: OUI | BM34: OUI | BN34: OUI | BO34: OUI | BP34: OUI | BQ34: OUI | BR34: OUI | BS34: OUI | BT34: OUI | BU34: OUI | BV34: OUI | BW34: OUI | BX34: OUI | BY34: OUI | BZ34: OUI | CA34: OUI | CB34: OUI | CC34: OUI | CD34: OUI | CE34: OUI | CF34: OUI | CG34: OUI | CH34: OUI | CI34: OUI | CJ34: OUI | CK34: OUI | CL34: OUI | CM34: OUI | CN34: OUI | CO34: OUI | CP34: OUI | CQ34: OUI | CR34: OUI | CS34: OUI | CT34: OUI | CU34: OUI | CV34: OUI | CW34: OUI | CX34: OUI | CY34: OUI | CZ34: OUI | DA34: OUI | DB34: OUI | DC34: OUI | DD34: OUI | DE34: OUI | DF34: OUI | DG34: OUI | DH34: OUI | DI34: OUI | DJ34: OUI | DK34: OUI | DL34: OUI | DM34: OUI | DN34: OUI | DO34: OUI | DP34: OUI | DQ34: OUI | DR34: OUI | DS34: OUI | DT34: OUI | DU34: OUI | DV34: OUI | DW34: OUI
